<robot name = "robot">
    <link name="0">
        <inertial>
            <origin xyz="0 0 0.6130969438749123" rpy="0 0 0"/>
            <mass value="1" />
            <inertia ixx="100" ixy="0" ixz="0" iyy="100" iyz="0" izz="100" />
        </inertial>
        <visual>
            <origin xyz="0 0 0.6130969438749123" rpy="0 0 0"/>
            <geometry>
                <box size="0.2654685243743693 1.2232740110121312 1.2261938877498246" />
            </geometry>
            <material name="cyan">
                <color rgba="0 1.0 1.0 1.0"/>
            </material>
        </visual>
        <collision>
            <origin xyz="0 0 0.6130969438749123" rpy="0 0 0"/>
            <geometry>
                <box size="0.2654685243743693 1.2232740110121312 1.2261938877498246" />
            </geometry>
        </collision>
    </link>
    <joint name="0_1" type="revolute">
       <parent link="0"/>
       <child  link="1"/>
       <origin rpy="0 0 0" xyz="0.05942037966875571 0.6116370055060656 0.43054596753843666" />
       <axis xyz="0 0 1"/>
       <limit effort="0.0" lower="-3.14159" upper="3.14159" velocity="0.0"/>
    </joint>
    <link name="1">
        <inertial>
            <origin xyz="0 0.6945486824987306 0" rpy="0 0 0"/>
            <mass value="1" />
            <inertia ixx="100" ixy="0" ixz="0" iyy="100" iyz="0" izz="100" />
        </inertial>
        <visual>
            <origin xyz="0 0.6945486824987306 0" rpy="0 0 0"/>
            <geometry>
                <box size="0.2399499551929954 1.3890973649974612 0.27631980982003407" />
            </geometry>
            <material name="cyan">
                <color rgba="0 1.0 1.0 1.0"/>
            </material>
        </visual>
        <collision>
            <origin xyz="0 0.6945486824987306 0" rpy="0 0 0"/>
            <geometry>
                <box size="0.2399499551929954 1.3890973649974612 0.27631980982003407" />
            </geometry>
        </collision>
    </link>
    <joint name="0_2" type="revolute">
       <parent link="0"/>
       <child  link="2"/>
       <origin rpy="0 0 0" xyz="-0.09188572785495112 -0.41023665510001317 1.2261938877498246" />
       <axis xyz="1 0 0"/>
       <limit effort="0.0" lower="-3.14159" upper="3.14159" velocity="0.0"/>
    </joint>
    <link name="2">
        <inertial>
            <origin xyz="0 0 0.39461870393394644" rpy="0 0 0"/>
            <mass value="1" />
            <inertia ixx="100" ixy="0" ixz="0" iyy="100" iyz="0" izz="100" />
        </inertial>
        <visual>
            <origin xyz="0 0 0.39461870393394644" rpy="0 0 0"/>
            <geometry>
                <box size="0.032596006916480846 0.10541950635963288 0.7892374078678929" />
            </geometry>
            <material name="cyan">
                <color rgba="0 1.0 1.0 1.0"/>
            </material>
        </visual>
        <collision>
            <origin xyz="0 0 0.39461870393394644" rpy="0 0 0"/>
            <geometry>
                <box size="0.032596006916480846 0.10541950635963288 0.7892374078678929" />
            </geometry>
        </collision>
    </link>
    <joint name="0_3" type="revolute">
       <parent link="0"/>
       <child  link="3"/>
       <origin rpy="0 0 0" xyz="0.0934854113866154 0.6116370055060656 1.0792568680939978" />
       <axis xyz="0 0 1"/>
       <limit effort="0.0" lower="-3.14159" upper="3.14159" velocity="0.0"/>
    </joint>
    <link name="3">
        <inertial>
            <origin xyz="0 0.5195092808648408 0" rpy="0 0 0"/>
            <mass value="1" />
            <inertia ixx="100" ixy="0" ixz="0" iyy="100" iyz="0" izz="100" />
        </inertial>
        <visual>
            <origin xyz="0 0.5195092808648408 0" rpy="0 0 0"/>
            <geometry>
                <box size="0.07375234235388084 1.0390185617296817 0.04449790546995064" />
            </geometry>
            <material name="cyan">
                <color rgba="0 1.0 1.0 1.0"/>
            </material>
        </visual>
        <collision>
            <origin xyz="0 0.5195092808648408 0" rpy="0 0 0"/>
            <geometry>
                <box size="0.07375234235388084 1.0390185617296817 0.04449790546995064" />
            </geometry>
        </collision>
    </link>
    <joint name="0_4" type="revolute">
       <parent link="0"/>
       <child  link="4"/>
       <origin rpy="0 0 0" xyz="0.13273426218718465 0.026126045936202047 0.11291494438569903" />
       <axis xyz="0 0 1"/>
       <limit effort="0.0" lower="-3.14159" upper="3.14159" velocity="0.0"/>
    </joint>
    <link name="4">
        <inertial>
            <origin xyz="0.382702585875469 0 0" rpy="0 0 0"/>
            <mass value="1" />
            <inertia ixx="100" ixy="0" ixz="0" iyy="100" iyz="0" izz="100" />
        </inertial>
        <visual>
            <origin xyz="0.382702585875469 0 0" rpy="0 0 0"/>
            <geometry>
                <box size="0.765405171750938 0.40520633816256596 0.008402180048944996" />
            </geometry>
            <material name="cyan">
                <color rgba="0 1.0 1.0 1.0"/>
            </material>
        </visual>
        <collision>
            <origin xyz="0.382702585875469 0 0" rpy="0 0 0"/>
            <geometry>
                <box size="0.765405171750938 0.40520633816256596 0.008402180048944996" />
            </geometry>
        </collision>
    </link>
    <joint name="0_5" type="revolute">
       <parent link="0"/>
       <child  link="5"/>
       <origin rpy="0 0 0" xyz="-0.09419832386929954 0.6116370055060656 0.03758213091478424" />
       <axis xyz="0 0 1"/>
       <limit effort="0.0" lower="-3.14159" upper="3.14159" velocity="0.0"/>
    </joint>
    <link name="5">
        <inertial>
            <origin xyz="0 0.3904946103509239 0" rpy="0 0 0"/>
            <mass value="1" />
            <inertia ixx="100" ixy="0" ixz="0" iyy="100" iyz="0" izz="100" />
        </inertial>
        <visual>
            <origin xyz="0 0.3904946103509239 0" rpy="0 0 0"/>
            <geometry>
                <box size="0.3110586911523323 0.7809892207018478 0.24919585819318724" />
            </geometry>
            <material name="cyan">
                <color rgba="0 1.0 1.0 1.0"/>
            </material>
        </visual>
        <collision>
            <origin xyz="0 0.3904946103509239 0" rpy="0 0 0"/>
            <geometry>
                <box size="0.3110586911523323 0.7809892207018478 0.24919585819318724" />
            </geometry>
        </collision>
    </link>
</robot>