<robot name = "robot">
    <link name="Link0">
        <inertial>
            <origin xyz="0 0 0.3" rpy="0 0 0"/>
            <mass value="1" />
            <inertia ixx="100" ixy="0" ixz="0" iyy="100" iyz="0" izz="100" />
        </inertial>
        <visual>
            <origin xyz="0 0 0.3" rpy="0 0 0"/>
            <geometry>
                <box size="0.5471109201794214 0.494838829967435 0.18890324347836876" />
            </geometry>
            <material name="cyan">
                <color rgba="0 1.0 1.0 1.0"/>
            </material>
        </visual>
        <collision>
            <origin xyz="0 0 0.3" rpy="0 0 0"/>
            <geometry>
                <box size="0.5471109201794214 0.494838829967435 0.18890324347836876" />
            </geometry>
        </collision>
    </link>
    <joint name="Link0_Link1" type="revolute">
       <parent link="Link0"/>
       <child  link="Link1"/>
       <origin rpy="0 0 0" xyz="0 0.2474194149837175 0.3" />
       <axis xyz="1 0 0"/>
       <limit effort="0.0" lower="-3.14159" upper="3.14159" velocity="0.0"/>
    </joint>
    <link name="Link1">
        <inertial>
            <origin xyz="0 0.4533564566377477 0" rpy="0 0 0"/>
            <mass value="1" />
            <inertia ixx="100" ixy="0" ixz="0" iyy="100" iyz="0" izz="100" />
        </inertial>
        <visual>
            <origin xyz="0 0.4533564566377477 0" rpy="0 0 0"/>
            <geometry>
                <box size="1.0966786066332916 0.9067129132754954 1.1863614334945194" />
            </geometry>
            <material name="green">
                <color rgba="0 1.0 0 1.0"/>
            </material>
        </visual>
        <collision>
            <origin xyz="0 0.4533564566377477 0" rpy="0 0 0"/>
            <geometry>
                <box size="1.0966786066332916 0.9067129132754954 1.1863614334945194" />
            </geometry>
        </collision>
    </link>
    <joint name="Link1_Link2" type="revolute">
       <parent link="Link1"/>
       <child  link="Link2"/>
       <origin rpy="0 0 0" xyz="0 0.9067129132754954 0" />
       <axis xyz="1 0 0"/>
       <limit effort="0.0" lower="-3.14159" upper="3.14159" velocity="0.0"/>
    </joint>
    <link name="Link2">
        <inertial>
            <origin xyz="0 0.20303950973192866 0" rpy="0 0 0"/>
            <mass value="1" />
            <inertia ixx="100" ixy="0" ixz="0" iyy="100" iyz="0" izz="100" />
        </inertial>
        <visual>
            <origin xyz="0 0.20303950973192866 0" rpy="0 0 0"/>
            <geometry>
                <box size="0.5099032540277433 0.4060790194638573 1.19729578547389" />
            </geometry>
            <material name="cyan">
                <color rgba="0 1.0 1.0 1.0"/>
            </material>
        </visual>
        <collision>
            <origin xyz="0 0.20303950973192866 0" rpy="0 0 0"/>
            <geometry>
                <box size="0.5099032540277433 0.4060790194638573 1.19729578547389" />
            </geometry>
        </collision>
    </link>
    <joint name="Link2_Link3" type="revolute">
       <parent link="Link2"/>
       <child  link="Link3"/>
       <origin rpy="0 0 0" xyz="0 0.4060790194638573 0" />
       <axis xyz="1 0 0"/>
       <limit effort="0.0" lower="-3.14159" upper="3.14159" velocity="0.0"/>
    </joint>
    <link name="Link3">
        <inertial>
            <origin xyz="0 0.5260770865703858 0" rpy="0 0 0"/>
            <mass value="1" />
            <inertia ixx="100" ixy="0" ixz="0" iyy="100" iyz="0" izz="100" />
        </inertial>
        <visual>
            <origin xyz="0 0.5260770865703858 0" rpy="0 0 0"/>
            <geometry>
                <box size="0.7047107183574421 1.0521541731407715 0.677277913405836" />
            </geometry>
            <material name="cyan">
                <color rgba="0 1.0 1.0 1.0"/>
            </material>
        </visual>
        <collision>
            <origin xyz="0 0.5260770865703858 0" rpy="0 0 0"/>
            <geometry>
                <box size="0.7047107183574421 1.0521541731407715 0.677277913405836" />
            </geometry>
        </collision>
    </link>
    <joint name="Link3_Link4" type="revolute">
       <parent link="Link3"/>
       <child  link="Link4"/>
       <origin rpy="0 0 0" xyz="0 1.0521541731407715 0" />
       <axis xyz="1 0 0"/>
       <limit effort="0.0" lower="-3.14159" upper="3.14159" velocity="0.0"/>
    </joint>
    <link name="Link4">
        <inertial>
            <origin xyz="0 0.41805805524217665 0" rpy="0 0 0"/>
            <mass value="1" />
            <inertia ixx="100" ixy="0" ixz="0" iyy="100" iyz="0" izz="100" />
        </inertial>
        <visual>
            <origin xyz="0 0.41805805524217665 0" rpy="0 0 0"/>
            <geometry>
                <box size="0.33827715943261455 0.8361161104843533 0.9531082949139518" />
            </geometry>
            <material name="green">
                <color rgba="0 1.0 0 1.0"/>
            </material>
        </visual>
        <collision>
            <origin xyz="0 0.41805805524217665 0" rpy="0 0 0"/>
            <geometry>
                <box size="0.33827715943261455 0.8361161104843533 0.9531082949139518" />
            </geometry>
        </collision>
    </link>
    <joint name="Link4_Link5" type="revolute">
       <parent link="Link4"/>
       <child  link="Link5"/>
       <origin rpy="0 0 0" xyz="0 0.8361161104843533 0" />
       <axis xyz="1 0 0"/>
       <limit effort="0.0" lower="-3.14159" upper="3.14159" velocity="0.0"/>
    </joint>
    <link name="Link5">
        <inertial>
            <origin xyz="0 0.5470772576359327 0" rpy="0 0 0"/>
            <mass value="1" />
            <inertia ixx="100" ixy="0" ixz="0" iyy="100" iyz="0" izz="100" />
        </inertial>
        <visual>
            <origin xyz="0 0.5470772576359327 0" rpy="0 0 0"/>
            <geometry>
                <box size="1.061440823953466 1.0941545152718655 0.810925211551816" />
            </geometry>
            <material name="cyan">
                <color rgba="0 1.0 1.0 1.0"/>
            </material>
        </visual>
        <collision>
            <origin xyz="0 0.5470772576359327 0" rpy="0 0 0"/>
            <geometry>
                <box size="1.061440823953466 1.0941545152718655 0.810925211551816" />
            </geometry>
        </collision>
    </link>
</robot>